# Error Handling (에러 처리)

에러에 응답하고 복구합니다.

에러 처리는 프로그램의 에러 조건에 응답하고 복구하는 프로세스입니다.

Swift 는 런타임에 복구 가능한 에러 발생, 포착, 전파 및 조작에 대한 최고 수준의 지원을 제공합니다.

#

일부 작업은 항상 실행을 완료하거나 유용한 출력을 생성한다고 보장되지 않습니다.

옵셔널은 값이 없음을 나타내는데 사용되지만 작업이 실패할 경우 코드가 그에 따라 응답할 수 있도록 실패의 원인을 이해하는 것이 유용한 경우가 많습니다.

#

예를 들어 디스크의 파일에서 데이터를 읽고 처리하는 작업을 생각해 보세요.

지정된 경로에 파일이 존재하지 않거나, 파일에 읽기 권한이 없거나, 파일이 적절한 형식으로 인코딩 되지 않은 경우를 포함하여 작업이 실패할 수 있는 여러가지 방법이 있습니다.

이러한 다양한 상황을 구별하면 프로그램에서 일부 에러를 해결하고 해결할 수 없는 에러를 사용자에게 전달할 수 있습니다.

> Note    
> Swift 의 에러 처리는 Cocoa 및 Objective-C 의 `NSError` 클래스를 사용하는 에러 처리 패턴과 상호 운용됩니다.
> 이 클래스에 대한 자세한 내용은 [Swift 에서 Cocoa 에러 처리 (Handling Cocoa Errors in Swift)]() 를 참조하세요.

<br>

## 에러 표현과 던지기 (Representing and Throwing Errors)

Swift 에서 에러는 `Error` 프로토콜을 준수하는 타입의 값으로 표시됩니다.

이 빈 프로토콜은 에러 처리에 타입을 사용할 수 있음을 나타냅니다.

#

Swift 열거형은 관련된 에러 조건의 그룹을 모델링하는데 특히 적합하며 관련 값을 사용하여 에러의 성격에 대한 추가 정보를 전달할 수 있습니다.

예를 들어 게임 내에서 자동 판매기 작동 에러 조건을 표현한느 방법은 다음과 같습니다.

~~~ swift
enum VendingMachineError: Error {
    case invalidSelection
    case insufficientFunds(coinsNeeded: Int)
    case outOfStock
}
~~~

#

에러를 발생시키면 예상치 못한 일이 발생하여 정상적인 실행 흐름을 계속할 수 없음을 나타낼 수 있습니다.

`throw` 구문을 사용하여 에러를 발생시킵니다.

예를 들어 아래의 코드는 자동 판매기에서 5개의 추가 코인이 필요함을 나타내는 에러를 발생시킵니다.

~~~ swift
throw VendingMachineError.insufficientFunds(coinsNeeded: 5)
~~~

<br>

## 에러 처리 (Handling Errors)

에러가 발생하면 주변 코드의 일부분이 에러 처리를 담당해야 합니다.

예를 들어 문제를 수정하거나 대체 접근 방식을 시도하거나 사용자에게 에러를 알리는 등의 작업을 수행합니다.

#

Swift 에는 에러를 처리하는 4가지 방법이 있습니다.

함수에서 해당 함수를 호출하는 코드로 에러를 전파하거나 `do-catch` 문을 사용하여 에러를 처리하거나 에러를 옵셔널 값으로 처리하거나 에러가 발생하지 않을 것이라고 주장할 수 있습니다.

각 접근 방식은 아래 섹션에 설명되어 있습니다.

#

함수에서 에러가 발생하면 프로그램의 흐름이 변경되므로 코드에서 에러가 발생할 수 있는 위치를 빠르게 식별할 수 있는 것이 중요합니다.

코드에서 이러한 위치를 식별하려면 에러를 발생시킬 수 있는 함수, 메서드 또는 초기화 구문을 호출하는 코드 조각 앞에 `try` 또는 `try?` 또는 `try!` 키워드를 작성합니다.

이러한 키워드는 아래 섹션에 설명되어 있습니다.

> Note    
> Swift 의 에러 처리는 `try`, `catch` 그리고 `throw` 키워드를 사용하는 다른 언어의 에러 처리와 유사합니다.
> Objective-C 를 포함한 많은 언어의 에러 처리와 달리 Swift 의 에러 처리에는 계산 비용이 많이 들 수 있는 프로세스인 호출 스택 해제가 포함되지 않습니다.
> 따라서 `throw` 문의 성능 특성은 `return` 문의 성능 특성과 비슷합니다.

<br>

### Throwing 함수를 이용한 에러 전파 (Propagating Errors Using Throwing Functions)

함수, 메서드 또는 초기화가 에러를 던질 수 있음을 나타내려면 함수의 선언에서 파라미터 뒤에 `throws` 키워드를 작성합니다.

`throws` 로 표시된 함수는 throw 함수 라고 합니다.

함수가 반환 타입을 지정하는 경우 반환 화살표 (`->`) 앞에 `throws` 키워드를 작성합니다.

~~~ swift
func canThrowErrors() throws -> String

func cannotThrowErrors() -> String
~~~

throw 함수는 함수 내부에서 발생한 에러를 호출된 범위로 전파합니다.

> Note    
> throw 함수만 에러를 전파할 수 있습니다.
> throws 선언이 되지 않은 함수 내에서 발생한 모든 에러는 함수 내에서 처리되어야 합니다.

#

아래 예제에서 `VendingMachine` 클래스는 요청한 항목을 사용할 수 없거나 재고가 없거나 현재 예치된 금액을 초과하는 비용이 있는 경우 적절한 `VendingMachineError` 를 던지는 `vend(itemNamed:)` 메서드를 가지고 있습니다.

~~~ swift
struct Item {
    var price: Int
    var count: Int
}


class VendingMachine {
    var inventory = [
        "Candy Bar": Item(price: 12, count: 7),
        "Chips": Item(price: 10, count: 4),
        "Pretzels": Item(price: 7, count: 11)
    ]
    var coinsDeposited = 0

    func vend(itemNamed name: String) throws {
        guard let item = inventory[name] else {
            throw VendingMachineError.invalidSelection
        }

        guard item.count > 0 else {
            throw VendingMachineError.outOfStock
        }

        guard item.price <= coinsDeposited else {
            throw VendingMachineError.insufficientFunds(coinsNeeded: item.price - coinsDeposited)
        }

        coinsDeposited -= item.price

        var newItem = item
        newItem.count -= 1
        inventory[name] = newItem

        print("Dispensing \(name)")
    }
}
~~~

`vend(itemNamed:)` 메서드의 구현은 `guard` 문을 사용하여 메서드를 일찍 종료시키고 간식 구매 요구사항 중 하나라도 충족되지 않으면 적절한 에러를 발생시킵니다.

`throw` 문은 프로그램 제어를 즉시 전달하기 때문에 모든 요구사항이 충족되는 경우에만 항목이 판매됩니다.

#

`vend(itemNamed:)` 메서드는 발생하는 모든 에러를 전파하기 때문에 이 메서드를 호출하는 코드는 `do-catch` 문, `try?` 또는 `try!` 를 사용하여 에러를 처리하거나 계속해서 전파해야 합니다.

예를 들어 아래 예제의 `buyFavoriteSnack(person:vendingMachine:)` 은 throw 함수이며 `vend(itemNamed:)` 메서드에서 발생한 모든 에러는 `buyFavoriteSnack(person:vendingMachine:)` 함수가 호출되는 지점까지 전파됩니다.

~~~ swift
let favoriteSnacks = [
    "Alice": "Chips",
    "Bob": "Licorice",
    "Eve": "Pretzels",
]
func buyFavoriteSnack(person: String, vendingMachine: VendingMachine) throws {
    let snackName = favoriteSnacks[person] ?? "Candy Bar"
    try vendingMachine.vend(itemNamed: snackName)
}
~~~

이 에제에서 `buyFavoriteSnack(person:vendingMachine:)` 함수는 주어진 사람의 좋아하는 간식을 찾고 `vending(itemNamed:)` 메서드를 호출하여 구매하려고 합니다.

`vend(itemNamed:)` 메서드는 에러를 발생시킬 수 있으므로 앞에 `try` 키워드를 붙여 호출합니다.

#

throw 초기화는 throw 함수와 같은 방법으로 에러를 전파할 수 있습니다.

예를 들어 아래 `PurchasedSnack` 구조체에 대한 초기화는 초기화 프로세스의 일부분으로 throw 함수를 호출하고 발생한 에러를 호출자에게 전파하여 처리합니다.

~~~ swift
struct PurchasedSnack {
    let name: String
    init(name: String, vendingMachine: VendingMachine) throws {
        try vendingMachine.vend(itemNamed: name)
        self.name = name
    }
}
~~~

<br>

### Do-Catch 를 사용하여 에러 처리 (Handling Errors Using Do-Catch)

`do-catch` 문을 사용하여 코드 블럭을 실행하여 에러를 처리합니다.

`do` 절의 코드에서 에러가 발생하면 에러를 처리할 수 있는 `catch` 절을 결정하기 위해 `do` 절과 일치시킵니다.

#

`do-catch` 문의 일반적인 형식은 다음과 같습니다.

~~~ swift
do {
    try <#expression#>
    <#statements#>
} catch <#pattern 1#> {
    <#statements#>
} catch <#pattern 2#> where <#condition#> {
    <#statements#>
} catch <#pattern 3#>, <#pattern 4#> where <#condition#> {
    <#statements#>
} catch {
    <#statements#>
}
~~~

해당 `catch` 절이 처리할 수 있는 에러를 나타내기 위해 `catch` 키워드 뒤에 패턴을 작성합니다.

`catch` 절에 패턴이 없는 경우 `catch` 절은 모든 에러와 일치하고 `error` 라는 이름을 가진 지역 상수에 바인딩합니다.

패턴 일치에 대한 자세한 내용은 [패턴 (Patterns)]() 을 참조하세요.

#

예를 들어 다음 코드는 `VendingMachineError` 열거형의 3가지 케이스 모두와 일치합니다.

~~~ swift
var vendingMachine = VendingMachine()
vendingMachine.coinsDeposited = 8
do {
    try buyFavoriteSnack(person: "Alice", vendingMachine: vendingMachine)
    print("Success! Yum.")
} catch VendingMachineError.invalidSelection {
    print("Invalid Selection.")
} catch VendingMachineError.outOfStock {
    print("Out of Stock.")
} catch VendingMachineError.insufficientFunds(let coinsNeeded) {
    print("Insufficient funds. Please insert an additional \(coinsNeeded) coins.")
} catch {
    print("Unexpected error: \(error).")
}
// Prints "Insufficient funds. Please insert an additional 2 coins."
~~~

위의 예제에서 `buyFavoriteSnack(person:vendingMachine)` 함수는 에러가 발생할 수 있으므로 `try` 표현식으로 호출됩니다.

에러가 발생하면 실행이 즉시 `catch` 절로 이전되어 전파를 계속 허용할지 여부를 결정합니다.

일치하는 패턴이 없으면 에러는 마지막 `catch` 절에 의해 포착되고 지역 상수 `error` 에 바인딩됩니다.

에러가 발생하지 않으면 `do` 구문의 나머지 명령문이 실행됩니다.

#

`catch` 절은 `do` 절에서 발생할 수 있는 모든 에러를 처리할 필요는 없습니다.

어떤 `catch` 절도 에러를 처리하지 않으면 에러가 주변 범위로 전파됩니다.

그러나 전파된 에러는 일부 주변 범위에서 처리되어야 합니다.

throw 하지 않는 함수에서는 `do-catch` 문에서 에러를 처리해야합니다.

throw 하는 함수에서는 `do-catch` 문이나 호출자가 에러를 처리해야 합니다.

에러가 처리되지 않고 최상위 범위로 전파되면 런타임 에러가 발생합니다.

#

예를 들어 위의 예제는 호출 함수에서 `VendingMachineError` 가 아닌 모든 에러를 포착하도록 작성할 수 있습니다.

~~~ swift
func nourish(with item: String) throws {
    do {
        try vendingMachine.vend(itemNamed: item)
    } catch is VendingMachineError {
        print("Couldn't buy that from the vending machine.")
    }
}

do {
    try nourish(with: "Beet-Flavored Chips")
} catch {
    print("Unexpected non-vending-machine-related error: \(error)")
}
// Prints "Couldn't buy that from the vending machine."
~~~

`nourish(with:)` 함수에서 `vend(itemNamed:)` 가 `VendingMachineError` 열거형의 케이스 중 하나의 에러를 발생시키면 `nourish(with:)` 는 메세지를 출력하여 에러를 처리합니다.

그렇지 않으면 `nourish(with:)` 는 호출 부분으로 에러를 전파합니다.

그런다음 일반 `catch` 절에서 에러를 포착합니다.

#

여러 관련 에러를 잡는 또 다른 방법은 `catch` 뒤에 콤마로 구분하여 나열하는 것입니다.

~~~ swift
func eat(item: String) throws {
    do {
        try vendingMachine.vend(itemNamed: item)
    } catch VendingMachineError.invalidSelection, VendingMachineError.insufficientFunds, VendingMachineError.outOfStock {
        print("Invalid selection, out of stock, or not enough money.")
    }
}
~~~

`eat(item:)` 함수는 포착할 자판기 에러를 나열하고 해당 에러 텍스트는 해당 목록의 항목에 해당합니다.

나열된 3가지 에러 중 하나라도 발생하면 이 `catch` 절은 메세지를 출력하여 처리합니다.

나중에 추가될 수 있는 자판기 에러를 포함하여 다른 모든 에러는 주변 범위로 전파됩니다.

<br>

### 에러를 옵셔널 값으로 변환 (Converting Errors to Optional Values)

에러를 옵셔널 값으로 변환하여 처리하기 위해 `try?` 를 사용합니다.

`try?` 표현식을 평가하는 동안 에러가 발생하면 표현식의 값은 `nil` 입니다.

예를 들어 아래 코드에서 `x` 와 `y` 는 동일한 값과 동작을 갖습니다.

~~~ swift
func someThrowingFunction() throws -> Int {
    // ...
}

let x = try? someThrowingFunction()

let y: Int?
do {
    y = try someThrowingFunction()
} catch {
    y = nil
}
~~~

`someThrowingFunction()` 이 에러가 발생하는 경우 `x` 와 `y` 의 값은 `nil` 입니다.

그렇지 않은 경우 `x` 와 `y` 의 값은 함수가 반환한 값입니다.

`x` 와 `y` 는 `someThrowingFunction()` 이 반환하는 타입의 옵셔널 입니다.

여기서 함수는 정수를 반환하므로 `x` 와 `y` 는 옵셔널 정수입니다.

#

`try?` 를 사용하면 모든 에러를 동일한 방식으로 처리하려는 경우 간결한 에러 처리 코드를 작성할 수 있습니다.

예를 들어 다음 코드는 여러 접근 방식을 사용하여 데이터를 가져오거나 모든 접근 방식이 실패할 경우 `nil` 을 반환합니다.

~~~ swift
func fetchData() -> Data? {
    if let data = try? fetchDataFromDisk() { return data }
    if let data = try? fetchDataFromServer() { return data }
    return nil
}
~~~

<br>

### 에러 전파 비활성화 (Disabling Error Propagation)

때로는 throw 함수나 메서드가 실제로 런타임에 에러를 던지지 않는다는 것을 알 수도 있습니다.

이러한 경우 표현식 앞에 `try!` 를 작성하여 에러 전파를 비활성화하고 에러가 발생하지 않는다는 런타임 어설션으로 호출을 래핑할 수 있습니다.

실제로 에러가 발생하면 런타임 에러가 발생합니다.

#

예를 들어 다음 코드는 지정된 경로에 이미지 리소스를 로드하거나 이미지를 로드할 수 없는 경우 에러를 발생시키는 `loadImage(atPath:)` 함수를 사용합니다.

이러한 경우 이미지가 애플리케이션과 함께 제공되어 런타임 시 에러가 발생하지 않으므로 에러 전파를 비활성화하는 것이 적절합니다.

~~~ swift
let photo = try! loadImage(atPath: "./Resources/John Appleseed.jpg")
~~~

<br>

## 에러 타입 지정 (Specifying the Error Type)

위의 모든 예제에서는 가장 일반적인 종류의 에러 처리를 사용하는데 코드가 실행중 발생할 수 있는 모든 에러는 `Error` 프로토콜을 준수하는 모든 타입의 값이 될 수 있습니다.

이 접근 방식은 코드가 실행되는 동안 발생할 수 있는 모든 에러를 미리 알 수 없다는 현실을 반영하며 특히 다른 곳에서 발생한 에러를 전파할 때 그렇습니다.

또한 에러가 시간이 지남에 따라 변경될 수 있다는 사실도 반영합니다.

라이브러리의 새로운 버전 (해당 라이브러리의 종속성을 포함) 에서 새로운 에러를 발생시킬 수 있으며 실제 사용자 구성의 풍부한 복잡성은 개발 또는 테스트 중에는 보이지 않았던 에러 모드를 노출시킬 수 있습니다.

위의 예제에서 에러 처리 코드는 특정 `catch` 절이 없는 에러를 처리하기 위해 기본 케이스가 항상 포함됩니다.

#

대부분의 Swift 코드에서는 발생하는 에러의 타입을 지정하지 않습니다.

그러나 다음과 같은 특별한 경우에는 코드가 특정 타입의 에러만 발생시키도록 제한할 수 있습니다.

- 동적 메모리 할당을 지원하지 않는 임베디드 시스템에서 코드를 실행하는 경우 `Error` 또는 다른 박스형 프로토콜 타입의 인스턴스를 발생시키려면 에러를 저장하기 위해 런타임에 메모리를 할당해야 합니다. 반면 특정 타입의 에러를 발생시키면 Swift 는 에러에 대한 힙 할당을 피할 수 있습니다.

- 에러가 라이브러리와 같은 코드의 일부 유닛의 구현 세부 사항이고 해당 코드에 대한 인터페이스의 일부가 아닌 경우 이러한 에러는 라이브러리에서만 발생하고 다른 종속성이나 라이브러리의 클라이언트에서 발생하지 않으므로 가능한 모든 실패 목록을 작성할 수 있습니다. 그리고 이러한 에러는 라이브러리의 구현 세부 사항이기 때문에 항상 해당 라이브러리 내에서 처리됩니다.

- 클로저 인수를 받고 해당 클로저의 에러를 전파하는 함수와 같이 일반 파라미터에 의해 설명된 에러만 전파하는 코드에서 특정 에러 타입 전파와 `rethrows` 사용 간의 비교는 `doc:Declarations:Rethrowing-Functions-and-Methods` 를 참조하세요.

#

예를 들어 다음과 같은 에러 타입을 사용하는 평점 요약 코드를 고려해 보세요.

~~~ swift
enum StatisticsError: Error {
    case noRatings
    case invalidRating(Int)
}
~~~






<br>

## 정리 작업 지정 (Specifying Cleanup Actions)

`defer` 문을 사용하여 코드 실행이 현재 코드 블럭을 떠나기 직전에 어떠한 작업을 실행합니다.

이 명령문을 사용하면 실행이 현재 코드 블럭을 어떻게 떠나는지와 관계없이 수행해야 하는 모든 필요한 정리 작업을 수행할 수 있습니다.

에러가 발생했거나 또는 `return` 또는 `break` 와 같은 명령문에 의해 종료되었는지 여부입니다.

예를 들어 `defer` 명령문을 사용하여 파일 설명자가 닫히고 수동으로 할당된 메모리가 해제되도록 할 수 있습니다.

#

`defer` 문은 현재 범위가 종료될 때까지 실행을 연기합니다.

이 명령문은 `defer` 키워드와 나중에 실행될 명령문으로 구성되어 있습니다.

지연된 구문은 `break` 또는 `return` 문과 같이 밖으로 제어를 전송하거나 에러를 발생시키는 코드를 포함할 수 없습니다.

지연된 작업은 소스 코드에 작성된 순서와 반대로 실행됩니다.

즉 첫번째 `defer` 문의 코드는 마지막으로 실행되고 두번째 `defer` 문의 코드는 마지막에서 두번째로 실행되는 식입니다.

소스 코드 순서의 마지막 `defer` 문이 가장 먼저 실행됩니다.

~~~ swift
func processFile(filename: String) throws {
    if exists(filename) {
        let file = open(filename)
        defer {
            close(file)
        }
        while let line = try file.readline() {
            // Work with the file.
        }
        // close(file) is called here, at the end of the scope.
    }
}
~~~

위의 에제에서는 `open(_:)` 함수에 `close(_:)` 에 대한 호출이 있는지 확인하기 위해 `defer` 문을 사용합니다.

#

에러 처리 코드가 관련되지 않은 경우에도 `defer` 문을 사용할 수 있습니다.

자세한 내용은 [지연된 작업 (Deferred Actions)]() 을 참조하세요.

***

### ⬅️ [Optional Chaining](https://github.com/Developer-Nova/Swift-Documentation/blob/main/Swift%20Documentation/2.Language%20Guide/16.Optional%20Chaining.md)

### ➡️ [Concurrency](https://github.com/Developer-Nova/Swift-Documentation/blob/main/Swift%20Documentation/2.Language%20Guide/18.Concurrency.md)
